🤖 Starting RASA training pipeline at Tue Jun 24 15:55:23 UTC 2025
🔍 Validating training data...
/Users/umitarslan/customer-care-ai/.venv/lib/python3.10/site-packages/rasa/core/tracker_store.py:1044: MovedIn20Warning: Deprecated API features detected! These feature(s) are not compatible with SQLAlchemy 2.0. To prevent incompatible upgrades prior to updating applications, ensure requirements files are pinned to "sqlalchemy<2.0". Set environment variable SQLALCHEMY_WARN_20=1 to show all deprecation warnings.  Set environment variable SQLALCHEMY_SILENCE_UBER_WARNING=1 to silence this message. (Background on SQLAlchemy 2.0 at: https://sqlalche.me/e/b8d9)
  Base: DeclarativeMeta = declarative_base()
/Users/umitarslan/customer-care-ai/.venv/lib/python3.10/site-packages/rasa/shared/utils/validation.py:134: DeprecationWarning: pkg_resources is deprecated as an API. See https://setuptools.pypa.io/en/latest/pkg_resources.html
  import pkg_resources
/Users/umitarslan/customer-care-ai/.venv/lib/python3.10/site-packages/pkg_resources/__init__.py:3117: DeprecationWarning: Deprecated call to `pkg_resources.declare_namespace('mpl_toolkits')`.
Implementing implicit namespace packages (as specified in PEP 420) is preferred to `pkg_resources.declare_namespace`. See https://setuptools.pypa.io/en/latest/references/keywords.html#keyword-namespace-packages
  declare_namespace(pkg)
/Users/umitarslan/customer-care-ai/.venv/lib/python3.10/site-packages/pkg_resources/__init__.py:3117: DeprecationWarning: Deprecated call to `pkg_resources.declare_namespace('ruamel')`.
Implementing implicit namespace packages (as specified in PEP 420) is preferred to `pkg_resources.declare_namespace`. See https://setuptools.pypa.io/en/latest/references/keywords.html#keyword-namespace-packages
  declare_namespace(pkg)
2025-06-24 15:55:28 INFO     rasa.validator  - Validating intents...
[93m/Users/umitarslan/customer-care-ai/.venv/lib/python3.10/site-packages/rasa/shared/utils/io.py:100: UserWarning: The intent 'affirm' is not used in any story or rule.
[0m[93m/Users/umitarslan/customer-care-ai/.venv/lib/python3.10/site-packages/rasa/shared/utils/io.py:100: UserWarning: The intent 'ask_return_policy' is not used in any story or rule.
[0m[93m/Users/umitarslan/customer-care-ai/.venv/lib/python3.10/site-packages/rasa/shared/utils/io.py:100: UserWarning: The intent 'check_balance' is not used in any story or rule.
[0m[93m/Users/umitarslan/customer-care-ai/.venv/lib/python3.10/site-packages/rasa/shared/utils/io.py:100: UserWarning: The intent 'check_order_status' is not used in any story or rule.
[0m[93m/Users/umitarslan/customer-care-ai/.venv/lib/python3.10/site-packages/rasa/shared/utils/io.py:100: UserWarning: The intent 'complaint' is not used in any story or rule.
[0m[93m/Users/umitarslan/customer-care-ai/.venv/lib/python3.10/site-packages/rasa/shared/utils/io.py:100: UserWarning: The intent 'contact_support' is not used in any story or rule.
[0m[93m/Users/umitarslan/customer-care-ai/.venv/lib/python3.10/site-packages/rasa/shared/utils/io.py:100: UserWarning: The intent 'deny' is not used in any story or rule.
[0m[93m/Users/umitarslan/customer-care-ai/.venv/lib/python3.10/site-packages/rasa/shared/utils/io.py:100: UserWarning: The intent 'need_help' is not used in any story or rule.
[0m[93m/Users/umitarslan/customer-care-ai/.venv/lib/python3.10/site-packages/rasa/shared/utils/io.py:100: UserWarning: The intent 'provide_info' is not used in any story or rule.
[0m[93m/Users/umitarslan/customer-care-ai/.venv/lib/python3.10/site-packages/rasa/shared/utils/io.py:100: UserWarning: The intent 'provide_order_number' is not used in any story or rule.
[0m[93m/Users/umitarslan/customer-care-ai/.venv/lib/python3.10/site-packages/rasa/shared/utils/io.py:100: UserWarning: The intent 'return_item' is not used in any story or rule.
[0m[93m/Users/umitarslan/customer-care-ai/.venv/lib/python3.10/site-packages/rasa/shared/utils/io.py:100: UserWarning: The intent 'thank' is not used in any story or rule.
[0m2025-06-24 15:55:28 INFO     rasa.validator  - Validating uniqueness of intents and stories...
2025-06-24 15:55:28 INFO     rasa.validator  - Validating utterances...
[93m/Users/umitarslan/customer-care-ai/.venv/lib/python3.10/site-packages/rasa/shared/utils/io.py:100: UserWarning: The utterance 'utter_order_status' is not used in any story or rule.
[0m[93m/Users/umitarslan/customer-care-ai/.venv/lib/python3.10/site-packages/rasa/shared/utils/io.py:100: UserWarning: The utterance 'utter_iamabot' is not used in any story or rule.
[0m[93m/Users/umitarslan/customer-care-ai/.venv/lib/python3.10/site-packages/rasa/shared/utils/io.py:100: UserWarning: The utterance 'utter_thank' is not used in any story or rule.
[0m[93m/Users/umitarslan/customer-care-ai/.venv/lib/python3.10/site-packages/rasa/shared/utils/io.py:100: UserWarning: The utterance 'utter_please_wait' is not used in any story or rule.
[0m[93m/Users/umitarslan/customer-care-ai/.venv/lib/python3.10/site-packages/rasa/shared/utils/io.py:100: UserWarning: The utterance 'utter_apologize_for_issue' is not used in any story or rule.
[0m[93m/Users/umitarslan/customer-care-ai/.venv/lib/python3.10/site-packages/rasa/shared/utils/io.py:100: UserWarning: The utterance 'utter_ask_anything_else' is not used in any story or rule.
[0m[93m/Users/umitarslan/customer-care-ai/.venv/lib/python3.10/site-packages/rasa/shared/utils/io.py:100: UserWarning: The utterance 'utter_thank_you' is not used in any story or rule.
[0m[93m/Users/umitarslan/customer-care-ai/.venv/lib/python3.10/site-packages/rasa/shared/utils/io.py:100: UserWarning: The utterance 'utter_default' is not used in any story or rule.
[0m[93m/Users/umitarslan/customer-care-ai/.venv/lib/python3.10/site-packages/rasa/shared/utils/io.py:100: UserWarning: The utterance 'utter_confirm' is not used in any story or rule.
[0m[93m/Users/umitarslan/customer-care-ai/.venv/lib/python3.10/site-packages/rasa/shared/utils/io.py:100: UserWarning: The utterance 'utter_joke' is not used in any story or rule.
[0m[93m/Users/umitarslan/customer-care-ai/.venv/lib/python3.10/site-packages/rasa/shared/utils/io.py:100: UserWarning: The utterance 'utter_human_handoff' is not used in any story or rule.
[0m[93m/Users/umitarslan/customer-care-ai/.venv/lib/python3.10/site-packages/rasa/shared/utils/io.py:100: UserWarning: The utterance 'utter_ask_order_number' is not used in any story or rule.
[0m[93m/Users/umitarslan/customer-care-ai/.venv/lib/python3.10/site-packages/rasa/shared/utils/io.py:100: UserWarning: The utterance 'utter_out_of_scope' is not used in any story or rule.
[0m[93m/Users/umitarslan/customer-care-ai/.venv/lib/python3.10/site-packages/rasa/shared/utils/io.py:100: UserWarning: The utterance 'utter_escalate_to_agent' is not used in any story or rule.
[0m[93m/Users/umitarslan/customer-care-ai/.venv/lib/python3.10/site-packages/rasa/shared/utils/io.py:100: UserWarning: The utterance 'utter_ask_rephrase' is not used in any story or rule.
[0m2025-06-24 15:55:28 INFO     rasa.validator  - Story structure validation...
Processed story blocks:   0%|          | 0/16 [00:00<?, ?it/s]Processed story blocks:   0%|          | 0/16 [00:00<?, ?it/s, # trackers=1]Processed story blocks:   0%|          | 0/16 [00:00<?, ?it/s, # trackers=1]Processed story blocks:   0%|          | 0/16 [00:00<?, ?it/s, # trackers=1]Processed story blocks:   0%|          | 0/16 [00:00<?, ?it/s, # trackers=1]Processed story blocks:   0%|          | 0/16 [00:00<?, ?it/s, # trackers=1]Processed story blocks:   0%|          | 0/16 [00:00<?, ?it/s, # trackers=1]Processed story blocks:   0%|          | 0/16 [00:00<?, ?it/s, # trackers=1]Processed story blocks:   0%|          | 0/16 [00:00<?, ?it/s, # trackers=1]Processed story blocks:   0%|          | 0/16 [00:00<?, ?it/s, # trackers=1]Processed story blocks:   0%|          | 0/16 [00:00<?, ?it/s, # trackers=1]Processed story blocks:   0%|          | 0/16 [00:00<?, ?it/s, # trackers=1]Processed story blocks:   0%|          | 0/16 [00:00<?, ?it/s, # trackers=1]Processed story blocks:   0%|          | 0/16 [00:00<?, ?it/s, # trackers=1]Processed story blocks:   0%|          | 0/16 [00:00<?, ?it/s, # trackers=1]Processed story blocks:   0%|          | 0/16 [00:00<?, ?it/s, # trackers=1]Processed story blocks:   0%|          | 0/16 [00:00<?, ?it/s, # trackers=1]Processed story blocks: 100%|██████████| 16/16 [00:00<00:00, 2884.42it/s, # trackers=1]
2025-06-24 15:55:28 INFO     rasa.core.training.story_conflict  - Considering all preceding turns for conflict analysis.
2025-06-24 15:55:28 INFO     rasa.validator  - No story structure conflicts found.
✅ Data validation successful
🚂 Training new model...
/Users/umitarslan/customer-care-ai/.venv/lib/python3.10/site-packages/rasa/core/tracker_store.py:1044: MovedIn20Warning: Deprecated API features detected! These feature(s) are not compatible with SQLAlchemy 2.0. To prevent incompatible upgrades prior to updating applications, ensure requirements files are pinned to "sqlalchemy<2.0". Set environment variable SQLALCHEMY_WARN_20=1 to show all deprecation warnings.  Set environment variable SQLALCHEMY_SILENCE_UBER_WARNING=1 to silence this message. (Background on SQLAlchemy 2.0 at: https://sqlalche.me/e/b8d9)
  Base: DeclarativeMeta = declarative_base()
/Users/umitarslan/customer-care-ai/.venv/lib/python3.10/site-packages/rasa/shared/utils/validation.py:134: DeprecationWarning: pkg_resources is deprecated as an API. See https://setuptools.pypa.io/en/latest/pkg_resources.html
  import pkg_resources
/Users/umitarslan/customer-care-ai/.venv/lib/python3.10/site-packages/pkg_resources/__init__.py:3117: DeprecationWarning: Deprecated call to `pkg_resources.declare_namespace('mpl_toolkits')`.
Implementing implicit namespace packages (as specified in PEP 420) is preferred to `pkg_resources.declare_namespace`. See https://setuptools.pypa.io/en/latest/references/keywords.html#keyword-namespace-packages
  declare_namespace(pkg)
/Users/umitarslan/customer-care-ai/.venv/lib/python3.10/site-packages/pkg_resources/__init__.py:3117: DeprecationWarning: Deprecated call to `pkg_resources.declare_namespace('ruamel')`.
Implementing implicit namespace packages (as specified in PEP 420) is preferred to `pkg_resources.declare_namespace`. See https://setuptools.pypa.io/en/latest/references/keywords.html#keyword-namespace-packages
  declare_namespace(pkg)
2025-06-24 15:55:30 INFO     rasa.cli.train  - Started validating domain and training data...
2025-06-24 15:55:32 INFO     rasa.validator  - Validating intents...
[93m/Users/umitarslan/customer-care-ai/.venv/lib/python3.10/site-packages/rasa/shared/utils/io.py:100: UserWarning: The intent 'affirm' is not used in any story or rule.
[0m[93m/Users/umitarslan/customer-care-ai/.venv/lib/python3.10/site-packages/rasa/shared/utils/io.py:100: UserWarning: The intent 'ask_return_policy' is not used in any story or rule.
[0m[93m/Users/umitarslan/customer-care-ai/.venv/lib/python3.10/site-packages/rasa/shared/utils/io.py:100: UserWarning: The intent 'check_balance' is not used in any story or rule.
[0m[93m/Users/umitarslan/customer-care-ai/.venv/lib/python3.10/site-packages/rasa/shared/utils/io.py:100: UserWarning: The intent 'check_order_status' is not used in any story or rule.
[0m[93m/Users/umitarslan/customer-care-ai/.venv/lib/python3.10/site-packages/rasa/shared/utils/io.py:100: UserWarning: The intent 'complaint' is not used in any story or rule.
[0m[93m/Users/umitarslan/customer-care-ai/.venv/lib/python3.10/site-packages/rasa/shared/utils/io.py:100: UserWarning: The intent 'contact_support' is not used in any story or rule.
[0m[93m/Users/umitarslan/customer-care-ai/.venv/lib/python3.10/site-packages/rasa/shared/utils/io.py:100: UserWarning: The intent 'deny' is not used in any story or rule.
[0m[93m/Users/umitarslan/customer-care-ai/.venv/lib/python3.10/site-packages/rasa/shared/utils/io.py:100: UserWarning: The intent 'need_help' is not used in any story or rule.
[0m[93m/Users/umitarslan/customer-care-ai/.venv/lib/python3.10/site-packages/rasa/shared/utils/io.py:100: UserWarning: The intent 'provide_info' is not used in any story or rule.
[0m[93m/Users/umitarslan/customer-care-ai/.venv/lib/python3.10/site-packages/rasa/shared/utils/io.py:100: UserWarning: The intent 'provide_order_number' is not used in any story or rule.
[0m[93m/Users/umitarslan/customer-care-ai/.venv/lib/python3.10/site-packages/rasa/shared/utils/io.py:100: UserWarning: The intent 'return_item' is not used in any story or rule.
[0m[93m/Users/umitarslan/customer-care-ai/.venv/lib/python3.10/site-packages/rasa/shared/utils/io.py:100: UserWarning: The intent 'thank' is not used in any story or rule.
[0m2025-06-24 15:55:32 INFO     rasa.validator  - Validating uniqueness of intents and stories...
2025-06-24 15:55:32 INFO     rasa.validator  - Validating utterances...
[93m/Users/umitarslan/customer-care-ai/.venv/lib/python3.10/site-packages/rasa/shared/utils/io.py:100: UserWarning: The utterance 'utter_default' is not used in any story or rule.
[0m[93m/Users/umitarslan/customer-care-ai/.venv/lib/python3.10/site-packages/rasa/shared/utils/io.py:100: UserWarning: The utterance 'utter_ask_rephrase' is not used in any story or rule.
[0m[93m/Users/umitarslan/customer-care-ai/.venv/lib/python3.10/site-packages/rasa/shared/utils/io.py:100: UserWarning: The utterance 'utter_human_handoff' is not used in any story or rule.
[0m[93m/Users/umitarslan/customer-care-ai/.venv/lib/python3.10/site-packages/rasa/shared/utils/io.py:100: UserWarning: The utterance 'utter_iamabot' is not used in any story or rule.
[0m[93m/Users/umitarslan/customer-care-ai/.venv/lib/python3.10/site-packages/rasa/shared/utils/io.py:100: UserWarning: The utterance 'utter_confirm' is not used in any story or rule.
[0m[93m/Users/umitarslan/customer-care-ai/.venv/lib/python3.10/site-packages/rasa/shared/utils/io.py:100: UserWarning: The utterance 'utter_escalate_to_agent' is not used in any story or rule.
[0m[93m/Users/umitarslan/customer-care-ai/.venv/lib/python3.10/site-packages/rasa/shared/utils/io.py:100: UserWarning: The utterance 'utter_thank' is not used in any story or rule.
[0m[93m/Users/umitarslan/customer-care-ai/.venv/lib/python3.10/site-packages/rasa/shared/utils/io.py:100: UserWarning: The utterance 'utter_please_wait' is not used in any story or rule.
[0m[93m/Users/umitarslan/customer-care-ai/.venv/lib/python3.10/site-packages/rasa/shared/utils/io.py:100: UserWarning: The utterance 'utter_order_status' is not used in any story or rule.
[0m[93m/Users/umitarslan/customer-care-ai/.venv/lib/python3.10/site-packages/rasa/shared/utils/io.py:100: UserWarning: The utterance 'utter_out_of_scope' is not used in any story or rule.
[0m[93m/Users/umitarslan/customer-care-ai/.venv/lib/python3.10/site-packages/rasa/shared/utils/io.py:100: UserWarning: The utterance 'utter_ask_order_number' is not used in any story or rule.
[0m[93m/Users/umitarslan/customer-care-ai/.venv/lib/python3.10/site-packages/rasa/shared/utils/io.py:100: UserWarning: The utterance 'utter_thank_you' is not used in any story or rule.
[0m[93m/Users/umitarslan/customer-care-ai/.venv/lib/python3.10/site-packages/rasa/shared/utils/io.py:100: UserWarning: The utterance 'utter_joke' is not used in any story or rule.
[0m[93m/Users/umitarslan/customer-care-ai/.venv/lib/python3.10/site-packages/rasa/shared/utils/io.py:100: UserWarning: The utterance 'utter_apologize_for_issue' is not used in any story or rule.
[0m[93m/Users/umitarslan/customer-care-ai/.venv/lib/python3.10/site-packages/rasa/shared/utils/io.py:100: UserWarning: The utterance 'utter_ask_anything_else' is not used in any story or rule.
[0m2025-06-24 15:55:32 INFO     rasa.validator  - Story structure validation...
Processed story blocks:   0%|          | 0/16 [00:00<?, ?it/s]Processed story blocks:   0%|          | 0/16 [00:00<?, ?it/s, # trackers=1]Processed story blocks:   0%|          | 0/16 [00:00<?, ?it/s, # trackers=1]Processed story blocks:   0%|          | 0/16 [00:00<?, ?it/s, # trackers=1]Processed story blocks:   0%|          | 0/16 [00:00<?, ?it/s, # trackers=1]Processed story blocks:   0%|          | 0/16 [00:00<?, ?it/s, # trackers=1]Processed story blocks:   0%|          | 0/16 [00:00<?, ?it/s, # trackers=1]Processed story blocks:   0%|          | 0/16 [00:00<?, ?it/s, # trackers=1]Processed story blocks:   0%|          | 0/16 [00:00<?, ?it/s, # trackers=1]Processed story blocks:   0%|          | 0/16 [00:00<?, ?it/s, # trackers=1]Processed story blocks:   0%|          | 0/16 [00:00<?, ?it/s, # trackers=1]Processed story blocks:   0%|          | 0/16 [00:00<?, ?it/s, # trackers=1]Processed story blocks:   0%|          | 0/16 [00:00<?, ?it/s, # trackers=1]Processed story blocks:   0%|          | 0/16 [00:00<?, ?it/s, # trackers=1]Processed story blocks:   0%|          | 0/16 [00:00<?, ?it/s, # trackers=1]Processed story blocks:   0%|          | 0/16 [00:00<?, ?it/s, # trackers=1]Processed story blocks:   0%|          | 0/16 [00:00<?, ?it/s, # trackers=1]Processed story blocks: 100%|██████████| 16/16 [00:00<00:00, 2791.78it/s, # trackers=1]
2025-06-24 15:55:32 INFO     rasa.core.training.story_conflict  - Considering all preceding turns for conflict analysis.
2025-06-24 15:55:32 INFO     rasa.validator  - No story structure conflicts found.
[93m/Users/umitarslan/customer-care-ai/.venv/lib/python3.10/site-packages/rasa/engine/recipes/recipe.py:35: FutureWarning: From Rasa Open Source 4.0.0 onwards it will be required to specify a recipe in your model configuration. Defaulting to recipe 'default.v1'.
  rasa.shared.utils.io.raise_deprecation_warning(
[0mTraceback (most recent call last):
  File "/Users/umitarslan/customer-care-ai/.venv/bin/rasa", line 8, in <module>
    sys.exit(main())
  File "/Users/umitarslan/customer-care-ai/.venv/lib/python3.10/site-packages/rasa/__main__.py", line 133, in main
    cmdline_arguments.func(cmdline_arguments)
  File "/Users/umitarslan/customer-care-ai/.venv/lib/python3.10/site-packages/rasa/cli/train.py", line 61, in <lambda>
    train_parser.set_defaults(func=lambda args: run_training(args, can_exit=True))
  File "/Users/umitarslan/customer-care-ai/.venv/lib/python3.10/site-packages/rasa/cli/train.py", line 101, in run_training
    training_result = train_all(
  File "/Users/umitarslan/customer-care-ai/.venv/lib/python3.10/site-packages/rasa/api.py", line 105, in train
    return train(
  File "/Users/umitarslan/customer-care-ai/.venv/lib/python3.10/site-packages/rasa/model_training.py", line 207, in train
    return _train_graph(
  File "/Users/umitarslan/customer-care-ai/.venv/lib/python3.10/site-packages/rasa/model_training.py", line 254, in _train_graph
    model_configuration = recipe.graph_config_for_recipe(
  File "/Users/umitarslan/customer-care-ai/.venv/lib/python3.10/site-packages/rasa/engine/recipes/default_recipe.py", line 216, in graph_config_for_recipe
    train_nodes, preprocessors = self._create_train_nodes(config, cli_parameters)
  File "/Users/umitarslan/customer-care-ai/.venv/lib/python3.10/site-packages/rasa/engine/recipes/default_recipe.py", line 237, in _create_train_nodes
    from rasa.graph_components.validators.default_recipe_validator import (
  File "/Users/umitarslan/customer-care-ai/.venv/lib/python3.10/site-packages/rasa/graph_components/validators/default_recipe_validator.py", line 12, in <module>
    from rasa.nlu.extractors.crf_entity_extractor import (
  File "/Users/umitarslan/customer-care-ai/.venv/lib/python3.10/site-packages/rasa/nlu/extractors/crf_entity_extractor.py", line 20, in <module>
    from rasa.nlu.test import determine_token_labels
  File "/Users/umitarslan/customer-care-ai/.venv/lib/python3.10/site-packages/rasa/nlu/test.py", line 34, in <module>
    import rasa.utils.plotting as plot_utils
  File "/Users/umitarslan/customer-care-ai/.venv/lib/python3.10/site-packages/rasa/utils/plotting.py", line 8, in <module>
    import matplotlib
  File "/Users/umitarslan/customer-care-ai/.venv/lib/python3.10/site-packages/matplotlib/__init__.py", line 109, in <module>
    from . import _api, _version, cbook, docstring, rcsetup
  File "/Users/umitarslan/customer-care-ai/.venv/lib/python3.10/site-packages/matplotlib/cbook/__init__.py", line 31, in <module>
    from matplotlib import _api, _c_internal_utils
ImportError: cannot import name '_c_internal_utils' from partially initialized module 'matplotlib' (most likely due to a circular import) (/Users/umitarslan/customer-care-ai/.venv/lib/python3.10/site-packages/matplotlib/__init__.py)
❌ Model training failed
