ü§ñ Starting RASA training pipeline at Tue Jun 24 15:49:47 UTC 2025
üîç Validating training data...
/Users/umitarslan/customer-care-ai/.venv/lib/python3.10/site-packages/rasa/core/tracker_store.py:1044: MovedIn20Warning: Deprecated API features detected! These feature(s) are not compatible with SQLAlchemy 2.0. To prevent incompatible upgrades prior to updating applications, ensure requirements files are pinned to "sqlalchemy<2.0". Set environment variable SQLALCHEMY_WARN_20=1 to show all deprecation warnings.  Set environment variable SQLALCHEMY_SILENCE_UBER_WARNING=1 to silence this message. (Background on SQLAlchemy 2.0 at: https://sqlalche.me/e/b8d9)
  Base: DeclarativeMeta = declarative_base()
/Users/umitarslan/customer-care-ai/.venv/lib/python3.10/site-packages/rasa/shared/utils/validation.py:134: DeprecationWarning: pkg_resources is deprecated as an API. See https://setuptools.pypa.io/en/latest/pkg_resources.html
  import pkg_resources
/Users/umitarslan/customer-care-ai/.venv/lib/python3.10/site-packages/pkg_resources/__init__.py:3117: DeprecationWarning: Deprecated call to `pkg_resources.declare_namespace('mpl_toolkits')`.
Implementing implicit namespace packages (as specified in PEP 420) is preferred to `pkg_resources.declare_namespace`. See https://setuptools.pypa.io/en/latest/references/keywords.html#keyword-namespace-packages
  declare_namespace(pkg)
/Users/umitarslan/customer-care-ai/.venv/lib/python3.10/site-packages/pkg_resources/__init__.py:3117: DeprecationWarning: Deprecated call to `pkg_resources.declare_namespace('ruamel')`.
Implementing implicit namespace packages (as specified in PEP 420) is preferred to `pkg_resources.declare_namespace`. See https://setuptools.pypa.io/en/latest/references/keywords.html#keyword-namespace-packages
  declare_namespace(pkg)
Traceback (most recent call last):
  File "/Users/umitarslan/customer-care-ai/.venv/lib/python3.10/site-packages/sklearn/__check_build/__init__.py", line 48, in <module>
    from ._check_build import check_build  # noqa
ModuleNotFoundError: No module named 'sklearn.__check_build._check_build'

During handling of the above exception, another exception occurred:

Traceback (most recent call last):
  File "/Users/umitarslan/customer-care-ai/.venv/bin/rasa", line 8, in <module>
    sys.exit(main())
  File "/Users/umitarslan/customer-care-ai/.venv/lib/python3.10/site-packages/rasa/__main__.py", line 133, in main
    cmdline_arguments.func(cmdline_arguments)
  File "/Users/umitarslan/customer-care-ai/.venv/lib/python3.10/site-packages/rasa/cli/data.py", line 122, in <lambda>
    func=lambda args: rasa.cli.utils.validate_files(
  File "/Users/umitarslan/customer-care-ai/.venv/lib/python3.10/site-packages/rasa/cli/utils.py", line 229, in validate_files
    from rasa.validator import Validator
  File "/Users/umitarslan/customer-care-ai/.venv/lib/python3.10/site-packages/rasa/validator.py", line 5, in <module>
    import rasa.core.training.story_conflict
  File "/Users/umitarslan/customer-care-ai/.venv/lib/python3.10/site-packages/rasa/core/training/story_conflict.py", line 6, in <module>
    from rasa.core.featurizers.tracker_featurizers import MaxHistoryTrackerFeaturizer
  File "/Users/umitarslan/customer-care-ai/.venv/lib/python3.10/site-packages/rasa/core/featurizers/tracker_featurizers.py", line 31, in <module>
    from rasa.core.featurizers.single_state_featurizer import SingleStateFeaturizer
  File "/Users/umitarslan/customer-care-ai/.venv/lib/python3.10/site-packages/rasa/core/featurizers/single_state_featurizer.py", line 8, in <module>
    from rasa.nlu.extractors.extractor import EntityTagSpec
  File "/Users/umitarslan/customer-care-ai/.venv/lib/python3.10/site-packages/rasa/nlu/extractors/extractor.py", line 30, in <module>
    import rasa.utils.train_utils
  File "/Users/umitarslan/customer-care-ai/.venv/lib/python3.10/site-packages/rasa/utils/train_utils.py", line 32, in <module>
    from rasa.utils.tensorflow.data_generator import RasaBatchDataGenerator
  File "/Users/umitarslan/customer-care-ai/.venv/lib/python3.10/site-packages/rasa/utils/tensorflow/data_generator.py", line 10, in <module>
    from rasa.utils.tensorflow.model_data import RasaModelData, Data, FeatureArray
  File "/Users/umitarslan/customer-care-ai/.venv/lib/python3.10/site-packages/rasa/utils/tensorflow/model_data.py", line 21, in <module>
    from sklearn.model_selection import train_test_split
  File "/Users/umitarslan/customer-care-ai/.venv/lib/python3.10/site-packages/sklearn/__init__.py", line 81, in <module>
    from . import __check_build  # noqa: F401
  File "/Users/umitarslan/customer-care-ai/.venv/lib/python3.10/site-packages/sklearn/__check_build/__init__.py", line 50, in <module>
    raise_build_error(e)
  File "/Users/umitarslan/customer-care-ai/.venv/lib/python3.10/site-packages/sklearn/__check_build/__init__.py", line 31, in raise_build_error
    raise ImportError(
ImportError: No module named 'sklearn.__check_build._check_build'
___________________________________________________________________________
Contents of /Users/umitarslan/customer-care-ai/.venv/lib/python3.10/site-packages/sklearn/__check_build:
__init__.py               __pycache__               setup.py
___________________________________________________________________________
It seems that scikit-learn has not been built correctly.

If you have installed scikit-learn from source, please do not forget
to build the package before using it: run `python setup.py install` or
`make` in the source directory.

If you have used an installer, please check that it is suited for your
Python version, your operating system and your platform.
‚ùå Data validation failed
