ü§ñ Starting RASA training pipeline at Tue Jun 24 15:54:32 UTC 2025
üîç Validating training data...
ModuleNotFoundError: No module named '_cffi_backend'
thread '<unnamed>' panicked at /Users/runner/.cargo/registry/src/index.crates.io-6f17d22bba15001f/pyo3-0.18.3/src/err/mod.rs:790:5:
Python API call failed
note: run with `RUST_BACKTRACE=1` environment variable to display a backtrace
Traceback (most recent call last):
  File "/Users/umitarslan/customer-care-ai/.venv/bin/rasa", line 5, in <module>
    from rasa.__main__ import main
  File "/Users/umitarslan/customer-care-ai/.venv/lib/python3.10/site-packages/rasa/__main__.py", line 15, in <module>
    from rasa.cli import (
  File "/Users/umitarslan/customer-care-ai/.venv/lib/python3.10/site-packages/rasa/cli/evaluate.py", line 7, in <module>
    from rasa.core.tracker_store import TrackerStore
  File "/Users/umitarslan/customer-care-ai/.venv/lib/python3.10/site-packages/rasa/core/tracker_store.py", line 27, in <module>
    from pymongo.collection import Collection
  File "/Users/umitarslan/customer-care-ai/.venv/lib/python3.10/site-packages/pymongo/__init__.py", line 92, in <module>
    from pymongo.mongo_client import MongoClient
  File "/Users/umitarslan/customer-care-ai/.venv/lib/python3.10/site-packages/pymongo/mongo_client.py", line 59, in <module>
    from pymongo import (
  File "/Users/umitarslan/customer-care-ai/.venv/lib/python3.10/site-packages/pymongo/uri_parser.py", line 23, in <module>
    from pymongo.client_options import _parse_ssl_options
  File "/Users/umitarslan/customer-care-ai/.venv/lib/python3.10/site-packages/pymongo/client_options.py", line 26, in <module>
    from pymongo.pool import PoolOptions
  File "/Users/umitarslan/customer-care-ai/.venv/lib/python3.10/site-packages/pymongo/pool.py", line 61, in <module>
    from pymongo.network import command, receive_message
  File "/Users/umitarslan/customer-care-ai/.venv/lib/python3.10/site-packages/pymongo/network.py", line 24, in <module>
    from pymongo import _csot, helpers, message, ssl_support
  File "/Users/umitarslan/customer-care-ai/.venv/lib/python3.10/site-packages/pymongo/ssl_support.py", line 22, in <module>
    import pymongo.pyopenssl_context as _ssl
  File "/Users/umitarslan/customer-care-ai/.venv/lib/python3.10/site-packages/pymongo/pyopenssl_context.py", line 26, in <module>
    from cryptography.x509 import load_der_x509_certificate as _load_der_x509_certificate
  File "/Users/umitarslan/customer-care-ai/.venv/lib/python3.10/site-packages/cryptography/x509/__init__.py", line 7, in <module>
    from cryptography.x509 import certificate_transparency
  File "/Users/umitarslan/customer-care-ai/.venv/lib/python3.10/site-packages/cryptography/x509/certificate_transparency.py", line 11, in <module>
    from cryptography.hazmat.bindings._rust import x509 as rust_x509
pyo3_runtime.PanicException: Python API call failed
‚ùå Data validation failed
